[2023-12-06 05:19:38,282] {taskinstance.py:896} INFO - Dependencies all met for <TaskInstance: booking_ingestion.load_data 2023-12-06T05:19:31.694077+00:00 [queued]>
[2023-12-06 05:19:38,311] {taskinstance.py:896} INFO - Dependencies all met for <TaskInstance: booking_ingestion.load_data 2023-12-06T05:19:31.694077+00:00 [queued]>
[2023-12-06 05:19:38,312] {taskinstance.py:1087} INFO - 
--------------------------------------------------------------------------------
[2023-12-06 05:19:38,312] {taskinstance.py:1088} INFO - Starting attempt 1 of 1
[2023-12-06 05:19:38,312] {taskinstance.py:1089} INFO - 
--------------------------------------------------------------------------------
[2023-12-06 05:19:38,353] {taskinstance.py:1107} INFO - Executing <Task(PythonOperator): load_data> on 2023-12-06T05:19:31.694077+00:00
[2023-12-06 05:19:38,357] {standard_task_runner.py:52} INFO - Started process 72 to run task
[2023-12-06 05:19:38,361] {standard_task_runner.py:76} INFO - Running: ['airflow', 'tasks', 'run', 'booking_ingestion', 'load_data', '2023-12-06T05:19:31.694077+00:00', '--job-id', '11', '--pool', 'default_pool', '--raw', '--subdir', 'DAGS_FOLDER/data_ingestion_dag/main.py', '--cfg-path', '/tmp/tmpmh14qcj_', '--error-file', '/tmp/tmp2n_cwwhg']
[2023-12-06 05:19:38,362] {standard_task_runner.py:77} INFO - Job 11: Subtask load_data
[2023-12-06 05:19:38,464] {logging_mixin.py:104} INFO - Running <TaskInstance: booking_ingestion.load_data 2023-12-06T05:19:31.694077+00:00 [running]> on host e4129730c035
[2023-12-06 05:19:38,713] {taskinstance.py:1300} INFO - Exporting the following env vars:
AIRFLOW_CTX_DAG_OWNER=airflow
AIRFLOW_CTX_DAG_ID=booking_ingestion
AIRFLOW_CTX_TASK_ID=load_data
AIRFLOW_CTX_EXECUTION_DATE=2023-12-06T05:19:31.694077+00:00
AIRFLOW_CTX_DAG_RUN_ID=manual__2023-12-06T05:19:31.694077+00:00
[2023-12-06 05:19:38,730] {taskinstance.py:1501} ERROR - Task failed with exception
Traceback (most recent call last):
  File "/home/airflow/.local/lib/python3.8/site-packages/airflow/models/taskinstance.py", line 1157, in _run_raw_task
    self._prepare_and_execute_task_with_callbacks(context, task)
  File "/home/airflow/.local/lib/python3.8/site-packages/airflow/models/taskinstance.py", line 1331, in _prepare_and_execute_task_with_callbacks
    result = self._execute_task(context, task_copy)
  File "/home/airflow/.local/lib/python3.8/site-packages/airflow/models/taskinstance.py", line 1361, in _execute_task
    result = task_copy.execute(context=context)
  File "/home/airflow/.local/lib/python3.8/site-packages/airflow/operators/python.py", line 150, in execute
    return_value = self.execute_callable()
  File "/home/airflow/.local/lib/python3.8/site-packages/airflow/operators/python.py", line 161, in execute_callable
    return self.python_callable(*self.op_args, **self.op_kwargs)
  File "/opt/airflow/dags/data_ingestion_dag/main.py", line 28, in load_data
    c.execute('''
sqlite3.OperationalError: near ")": syntax error
[2023-12-06 05:19:38,744] {taskinstance.py:1544} INFO - Marking task as FAILED. dag_id=booking_ingestion, task_id=load_data, execution_date=20231206T051931, start_date=20231206T051938, end_date=20231206T051938
[2023-12-06 05:19:38,857] {local_task_job.py:151} INFO - Task exited with return code 1
